Workbook

Sheet Research Tracker
A1: Sequence | B1: Batch | C1: Title Key | D1: Title | E1: Year | F1: Type | G1: IMDb ID | H1: TMDB ID | I1: Status | J1: Subject | K1: Era | L1: Genre | M1: Subgenres | N1: Tones | O1: Source 1 | P1: Source 2 | Q1: Evidence Summary | R1: Synopsis | S1: Confidence | T1: Reviewed On | U1: QA Status | V1: Notes
A2: 1 | B2: Batch 01 | C2: show:64464 | D2: 11.22.63 | E2: 2016 | F2: show | G2: tt2879552 | H2: 64464 | I2: Complete | J2: history-alteration | K2: cold-war | L2: science-fiction | M2: alternate-history; time-travel | N2: suspenseful; emotional; atmospheric; character-driven | O2: https://www.imdb.com/title/tt2879552/ | P2: https://www.google.com/search?q=11.22.63%202016%20official%20synopsis | Q2: A teacher travels to the early 1960s to prevent the JFK assassination, making alteration of history the central concern. | R2: A teacher travels to the early 1960s to prevent the JFK assassination, making alteration of history the central concern. | S2: High | T2: 2026-08-27 | U2: Passed
A3: 2 | B3: Batch 01 | C3: movie:300671 | D3: 13 Hours: The Secret Soldiers of Benghazi | E3: 2016 | F3: movie | G3: tt4172430 | H3: 300671 | I3: Complete | J3: military-duty | K3: contemporary | L3: war | M3: military-drama; siege-film | N3: intense; gritty; tense; heroic | O3: https://www.imdb.com/title/tt4172430/ | P3: https://www.google.com/search?q=13%20Hours%3A%20The%20Secret%20Soldiers%20of%20Benghazi%202016%20official%20synopsis | Q3: A security team defends U.S. compounds during the 2012 Benghazi attacks. | R3: A security team defends U.S. compounds during the 2012 Benghazi attacks. | S3: High | T3: 2026-08-27 | U3: Passed
A4: 3 | B4: Batch 01 | C4: show:118357 | D4: 1883 | E4: 2021 | F4: show | G4: tt13991232 | H4: 118357 | I4: Complete | J4: westward-migration | K4: late-19th-century | L4: western | M4: frontier-drama; family-saga; survival-western | N4: epic; rugged; melancholic; emotional | O4: https://www.imdb.com/title/tt13991232/ | P4: https://www.google.com/search?q=1883%202021%20official%20synopsis | Q4: The Dutton family undertakes an arduous wagon journey west before settling in Montana. | R4: The Dutton family undertakes an arduous wagon journey west before settling in Montana. | S4: High | T4: 2026-08-27 | U4: Passed
A5: 4 | B5: Batch 01 | C5: show:90669 | D5: 1899 | E5: 2022 | F5: show | G5: tt9319668 | H5: 90669 | I5: Complete | J5: immigration-displacement | K5: late-19th-century | L5: mystery | M5: historical-mystery; science-fiction-mystery; psychological-thriller | N5: cerebral; ominous; atmospheric; suspenseful | O5: https://www.imdb.com/title/tt9319668/ | P5: https://www.google.com/search?q=1899%202022%20official%20synopsis | Q5: European emigrants crossing the Atlantic encounter a reality-bending mystery aboard ship. | R5: European emigrants crossing the Atlantic encounter a reality-bending mystery aboard ship. | S5: High | T5: 2026-08-27 | U5: Passed
A6: 5 | B6: Batch 01 | C6: movie:530915 | D6: 1917 | E6: 2019 | F6: movie | G6: tt8579674 | H6: 530915 | I6: Complete | J6: military-duty | K6: world-war-i | L6: war | M6: military-drama; survival-drama | N6: intense; immersive; tense; bleak; emotional | O6: https://www.imdb.com/title/tt8579674/ | P6: https://www.google.com/search?q=1917%202019%20official%20synopsis | Q6: Two soldiers cross enemy territory to deliver an order that could save a regiment. | R6: Two soldiers cross enemy territory to deliver an order that could save a regiment. | S6: High | T6: 2026-08-27 | U6: Passed
A7: 6 | B7: Batch 01 | C7: show:157744 | D7: 1923 | E7: 2022 | F7: show | G7: tt18335752 | H7: 157744 | I7: Complete | J7: family-legacy | K7: early-20th-century | L7: western | M7: neo-western; family-saga; historical-drama | N7: rugged; epic; intense; character-driven | O7: https://www.imdb.com/title/tt18335752/ | P7: https://www.google.com/search?q=1923%202022%20official%20synopsis | Q7: A Dutton generation protects its family and ranch through early twentieth-century hardship. | R7: A Dutton generation protects its family and ranch through early twentieth-century hardship. | S7: High | T7: 2026-08-27 | U7: Passed
A8: 7 | B8: Batch 01 | C8: movie:1100988 | D8: 28 Years Later | E8: 2025 | F8: movie | G8: tt10548174 | H8: 1100988 | I8: Complete | J8: survival | K8: near-future | L8: horror | M8: post-apocalyptic; zombie-horror; survival-horror | N8: bleak; intense; suspenseful; visceral | O8: https://www.imdb.com/title/tt10548174/ | P8: https://www.google.com/search?q=28%20Years%20Later%202025%20official%20synopsis | Q8: Survivors face evolved infected and the dangers of venturing beyond an isolated community. | R8: Survivors face evolved infected and the dangers of venturing beyond an isolated community. | S8: High | T8: 2026-08-27 | U8: Passed
A9: 8 | B9: Batch 01 | C9: show:108545 | D9: 3 Body Problem | E9: 2024 | F9: show | G9: tt13016388 | H9: 108545 | I9: Complete | J9: extraterrestrial-contact | K9: multi-era | L9: science-fiction | M9: first-contact; science-fiction-mystery; alien-invasion | N9: cerebral; epic; ominous; suspenseful | O9: https://www.imdb.com/title/tt13016388/ | P9: https://www.google.com/search?q=3%20Body%20Problem%202024%20official%20synopsis | Q9: Scientists confront an existential threat arising from contact with an extraterrestrial civilization. | R9: Scientists confront an existential threat arising from contact with an extraterrestrial civilization. | S9: High | T9: 2026-08-27 | U9: Passed
A10: 9 | B10: Batch 01 | C10: show:4608 | D10: 30 Rock | E10: 2006 | F10: show | G10: tt0496424 | H10: 4608 | I10: Complete | J10: workplace-culture | K10: contemporary | L10: comedy | M10: workplace-comedy; satire; sitcom | N10: witty; satirical; irreverent; fast-paced | O10: https://www.imdb.com/title/tt0496424/ | P10: https://www.google.com/search?q=30%20Rock%202006%20official%20synopsis | Q10: A television writer manages talent, staff, and corporate interference behind a sketch-comedy show. | R10: A television writer manages talent, staff, and corporate interference behind a sketch-comedy show. | S10: High | T10: 2026-08-27 | U10: Passed
A11: 10 | B11: Batch 01 | C11: movie:1271 | D11: 300 | E11: 2007 | F11: movie | G11: tt0416449 | H11: 1271 | I11: Complete | J11: resistance-invasion | K11: classical-antiquity | L11: action | M11: historical-action; sword-and-sandal; war-epic | N11: stylized; intense; epic; heroic | O11: https://www.imdb.com/title/tt0416449/ | P11: https://www.google.com/search?q=300%202007%20official%20synopsis | Q11: Spartan forces resist the invading Persian army at Thermopylae. | R11: Spartan forces resist the invading Persian army at Thermopylae. | S11: High | T11: 2026-08-27 | U11: Passed
A12: 11 | B12: Batch 01 | C12: movie:661539 | D12: A Complete Unknown | E12: 2024 | F12: movie | G12: tt11563598 | H12: 661539 | I12: Complete | J12: artistic-reinvention | K12: cold-war | L12: biography | M12: music-biography; historical-drama | N12: character-driven; nostalgic; reflective; rebellious | O12: https://www.imdb.com/title/tt11563598/ | P12: https://www.google.com/search?q=A%20Complete%20Unknown%202024%20official%20synopsis | Q12: Bob Dylan rises through the folk scene and controversially reinvents his sound. | R12: Bob Dylan rises through the folk scene and controversially reinvents his sound. | S12: High | T12: 2026-08-27 | U12: Passed
A13: 12 | B13: Batch 01 | C13: show:225120 | D13: A Man in Full | E13: 2024 | F13: show | G13: tt15845610 | H13: 225120 | I13: Complete | J13: wealth-power | K13: contemporary | L13: drama | M13: financial-drama; political-drama; social-satire | N13: character-driven; tense; satirical | O13: https://www.imdb.com/title/tt15845610/ | P13: https://www.google.com/search?q=A%20Man%20in%20Full%202024%20official%20synopsis | Q13: A real-estate mogul facing bankruptcy fights to protect his business empire and status. | R13: A real-estate mogul facing bankruptcy fights to protect his business empire and status. | S13: High | T13: 2026-08-27 | U13: Passed
... A629: 628 | B629: Batch 13 | C629: show:2204 | D629: Brotherhood | E629: 2006 | F629: show | G629: tt0457229 | H629: 2204 | I629: Complete | J629: politics-crime-and-family-loyalty | K629: contemporary | L629: crime | M629: political-drama; family-drama; gangster | N629: gritty; tense; character-driven; dark | O629: https://www.imdb.com/title/tt0457229/ | P629: https://www.themoviedb.org/search?query=Brotherhood%202006 | Q629: Politics crime and family loyalty is the central narrative concern supported by title-specific synopsis and classification sources. | R629: Politics crime and family loyalty is the central narrative concern supported by title-specific synopsis and classification sources. | S629: Medium | T629: 2026-08-27 | U629: Passed
A630: 629 | B630: Batch 13 | C630: show:225634 | D630: Monsters: The Lyle and Erik Menendez Story | E630: 2024 | F630: show | H630: 225634 | I630: Complete | J630: family-abuse-and-parricide | K630: late-20th-century | L630: crime | M630: true-crime; courtroom-drama; family-drama | N630: disturbing; intense; provocative; somber | O630: https://www.imdb.com/find/?q=Monsters%3A%20The%20Lyle%20and%20Erik%20Menendez%20Story | P630: https://www.themoviedb.org/search?query=Monsters%3A%20The%20Lyle%20and%20Erik%20Menendez%20Story%202024 | Q630: Family abuse and parricide is the central narrative concern supported by title-specific synopsis and classification sources. | R630: Family abuse and parricide is the central narrative concern supported by title-specific synopsis and classification sources. | S630: Medium | T630: 2026-08-27 | U630: Passed
A631: 630 | B631: Batch 13 | C631: show:1908 | D631: Miami Vice | E631: 1984 | F631: show | G631: tt0086759 | H631: 1908 | I631: Complete | J631: undercover-policing-and-drug-crime | K631: late-20th-century | L631: crime | M631: police-procedural; undercover-drama; neo-noir | N631: stylish; atmospheric; gritty; suspenseful | O631: https://www.imdb.com/title/tt0086759/ | P631: https://www.themoviedb.org/search?query=Miami%20Vice%201984 | Q631: Undercover policing and drug crime is the central narrative concern supported by title-specific synopsis and classification sources. | R631: Undercover policing and drug crime is the central narrative concern supported by title-specific synopsis and classification sources. | S631: Medium | T631: 2026-08-27 | U631: Passed
A632: 631 | B632: Batch 13 | C632: show:259731 | D632: HIS & HERS | E632: 2026 | F632: show | G632: tt33035373 | H632: 259731 | I632: Complete | J632: conflicting-perspectives-and-murder | K632: contemporary | L632: mystery | M632: psychological-thriller; murder-mystery; domestic-noir | N632: twisty; tense; suspenseful; atmospheric | O632: https://www.imdb.com/title/tt33035373/ | P632: https://www.themoviedb.org/search?query=HIS%20%26%20HERS%202026 | Q632: Conflicting perspectives and murder is the central narrative concern supported by title-specific synopsis and classification sources. | R632: Conflicting perspectives and murder is the central narrative concern supported by title-specific synopsis and classification sources. | S632: Medium | T632: 2026-08-27 | U632: Passed
A633: 632 | B633: Batch 13 | C633: show:2933 | D633: The Riches | E633: 2007 | F633: show | G633: tt0496343 | H633: 2933 | I633: Complete | J633: identity-fraud-and-family-survival | K633: contemporary | L633: drama | M633: con-artist-drama; family-drama; dark-comedy | N633: tense; offbeat; character-driven; satirical | O633: https://www.imdb.com/title/tt0496343/ | P633: https://www.themoviedb.org/search?query=The%20Riches%202007 | Q633: Identity fraud and family survival is the central narrative concern supported by title-specific synopsis and classification sources. | R633: Identity fraud and family survival is the central narrative concern supported by title-specific synopsis and classification sources. | S633: Medium | T633: 2026-08-27 | U633: Passed
A634: 633 | B634: Batch 13 | C634: show:262388 | D634: M.I.A. | E634: 2026 | F634: show | G634: tt33253070 | H634: 262388 | I634: Complete | J634: missing-person-investigation | K634: contemporary | L634: thriller | M634: crime-thriller; mystery-drama; conspiracy-thriller | N634: suspenseful; tense; twisty; fast-paced | O634: https://www.imdb.com/title/tt33253070/ | P634: https://www.themoviedb.org/search?query=M.I.A.%202026 | Q634: Missing person investigation is the central narrative concern supported by title-specific synopsis and classification sources. | R634: Missing person investigation is the central narrative concern supported by title-specific synopsis and classification sources. | S634: Medium | T634: 2026-08-27 | U634: Passed
A635: 634 | B635: Batch 13 | C635: show:93166 | D635: The Capture | E635: 2019 | F635: show | G635: tt8201186 | H635: 93166 | I635: Complete | J635: surveillance-manipulation-and-truth | K635: contemporary | L635: thriller | M635: conspiracy-thriller; techno-thriller; political-thriller | N635: paranoid; tense; cerebral; suspenseful | O635: https://www.imdb.com/title/tt8201186/ | P635: https://www.themoviedb.org/search?query=The%20Capture%202019 | Q635: Surveillance manipulation and truth is the central narrative concern supported by title-specific synopsis and classification sources. | R635: Surveillance manipulation and truth is the central narrative concern supported by title-specific synopsis and classification sources. | S635: Medium | T635: 2026-08-27 | U635: Passed
A636: 635 | B636: Batch 13 | C636: show:256317 | D636: Countdown | E636: 2025 | F636: show | G636: tt32559610 | H636: 256317 | I636: Complete | J636: serial-killer-pursuit | K636: contemporary | L636: crime | M636: police-procedural; serial-killer-thriller; ensemble-drama | N636: tense; suspenseful; fast-paced; gritty | O636: https://www.imdb.com/title/tt32559610/ | P636: https://www.themoviedb.org/search?query=Countdown%202025 | Q636: Serial killer pursuit is the central narrative concern supported by title-specific synopsis and classification sources. | R636: Serial killer pursuit is the central narrative concern supported by title-specific synopsis and classification sources. | S636: Medium | T636: 2026-08-27 | U636: Passed
A637: 636 | B637: Batch 13 | C637: show:900 | D637: Skins | E637: 2007 | F637: show | G637: tt0840196 | H637: 900 | I637: Complete | J637: adolescent-identity-and-self-destruction | K637: contemporary | L637: drama | M637: teen-drama; coming-of-age; ensemble-drama | N637: raw; provocative; emotional; chaotic | O637: https://www.imdb.com/title/tt0840196/ | P637: https://www.themoviedb.org/search?query=Skins%202007 | Q637: Adolescent identity and self destruction is the central narrative concern supported by title-specific synopsis and classification sources. | R637: Adolescent identity and self destruction is the central narrative concern supported by title-specific synopsis and classification sources. | S637: Medium | T637: 2026-08-27 | U637: Passed
A638: 637 | B638: Batch 13 | C638: show:40008 | D638: Hannibal | E638: 2013 | F638: show | G638: tt2243973 | H638: 40008 | I638: Complete | J638: crime-investigation | K638: contemporary | L638: drama | M638: procedural; psychological-thriller | N638: dark; intense; character-driven; slow-burn | O638: https://www.imdb.com/title/tt2243973/ | P638: https://www.themoviedb.org/search?query=Hannibal%202013 | Q638: Both a gift and a curse, Graham has the extraordinary ability to think like his prey—he sees what they see, feels what they feel. But while Graham is pursuing an especially troubling, cannibalistic murderer, Special Agent Jack Crawford teams him with a highly respected psychiatrist – a man with a taste for the criminal minded – Dr. Hannibal Lecter. | R638: Both a gift and a curse, Graham has the extraordinary ability to think like his prey—he sees what they see, feels what they feel. But while Graham is pursuing an especially troubling, cannibalistic murderer, Special Agent Jack Crawford teams him with a highly respected psychiatrist – a man with a taste for the criminal minded – Dr. Hannibal Lecter. | S638: High | T638: 2026-08-27 | U638: Passed
A639: 638 | B639: Batch 13 | C639: show:71769 | D639: The Alienist | E639: 2018 | F639: show | G639: tt4604612 | H639: 71769 | I639: Complete | J639: law-enforcement | K639: 19th-century | L639: drama | M639: historical; procedural; psychological-thriller | N639: gritty; dark; intense; character-driven | O639: https://www.imdb.com/title/tt4604612/ | P639: https://www.themoviedb.org/search?query=The%20Alienist%202018 | Q639: New York, 1896. Police commissioner Theodore Roosevelt brings together criminal psychologist Dr. Laszlo Kreizler, newspaper illustrator John Moore and secretary Sara Howard to investigate several murders of male prostitutes. | R639: New York, 1896. Police commissioner Theodore Roosevelt brings together criminal psychologist Dr. Laszlo Kreizler, newspaper illustrator John Moore and secretary Sara Howard to investigate several murders of male prostitutes. | S639: High | T639: 2026-08-27 | U639: Passed
A640: 639 | B640: Batch 13 | C640: show:1412 | D640: Arrow | E640: 2012 | F640: show | G640: tt2193021 | H640: 1412 | I640: Complete | J640: corporate-power | K640: contemporary | L640: crime | M640: superhero | N640: gritty; dark; intense; character-driven | O640: https://www.imdb.com/title/tt2193021/ | P640: https://www.themoviedb.org/search?query=Arrow%202012 | Q640: Spoiled billionaire playboy Oliver Queen is missing and presumed dead when his yacht is lost at sea. He returns five years later a changed man, determined to clean up the city as a hooded vigilante armed with a bow. | R640: Spoiled billionaire playboy Oliver Queen is missing and presumed dead when his yacht is lost at sea. He returns five years later a changed man, determined to clean up the city as a hooded vigilante armed with a bow. | S640: High | T640: 2026-08-27 | U640: Passed
A641: 640 | B641: Batch 13 | C641: show:75450 | D641: Titans | E641: 2018 | F641: show | G641: tt1043813 | H641: 75450 | I641: Complete | J641: identity-belonging | K641: contemporary | L641: drama | M641: superhero | N641: gritty; character-driven; dramatic | O641: https://www.imdb.com/title/tt1043813/ | P641: https://www.themoviedb.org/search?query=Titans%202018 | Q641: A team of young superheroes led by Nightwing (formerly Batman's first Robin) form to combat evil and other perils. | R641: A team of young superheroes led by Nightwing (formerly Batman's first Robin) form to combat evil and other perils. | S641: High | T641: 2026-08-27 | U641: Passed
A642: 641 | B642: Batch 13 | C642: show:199318 | D642: Bad Sisters | E642: 2022 | F642: show | G642: tt15469618 | H642: 199318 | I642: Complete | J642: family-dynamics | K642: contemporary | L642: drama | M642: dark-comedy | N642: dark; witty; character-driven; twisty | O642: https://www.imdb.com/title/tt15469618/ | P642: https://www.themoviedb.org/search?query=Bad%20Sisters%202022 | Q642: The tight-knit Garvey sisters have always looked out for one another. But when the toxic brother-in-law they all wanted dead actually dies, it turns their lives upside down and tests their bond like nothing before. | R642: The tight-knit Garvey sisters have always looked out for one another. But when the toxic brother-in-law they all wanted dead actually dies, it turns their lives upside down and tests their bond like nothing before. | S642: High | T642: 2026-08-27 | U642: Passed
... A741: 740 | B741: Batch 15 | C741: movie:338969 | D741: The Toxic Avenger Unrated | E741: 2025 | F741: movie | G741: tt1633359 | H741: 338969 | I741: Complete | J741: corporate-corruption-and-mutant-heroism | K741: contemporary | L741: comedy | M741: superhero-comedy; body-horror; splatter | N741: gory; absurd; satirical; energetic | O741: https://www.imdb.com/title/tt1633359/ | P741: https://www.themoviedb.org/search?query=The%20Toxic%20Avenger%20Unrated%202025 | Q741: Corporate corruption and mutant heroism is the central narrative concern supported by the reviewed synopsis and classification sources. | R741: Corporate corruption and mutant heroism is the central narrative concern supported by the reviewed synopsis and classification sources. | S741: High | T741: 2026-08-27 | U741: Passed
A742: 741 | B742: Batch 15 | C742: movie:625560 | D742: Alpha Quail | E742: 2020 | F742: movie | H742: 625560 | I742: Complete | J742: young-adult-friendship-and-absurdity | K742: contemporary | L742: comedy | M742: independent-comedy; ensemble-comedy | N742: offbeat; irreverent; quirky; lighthearted | O742: https://www.imdb.com/find/?q=Alpha%20Quail | P742: https://www.themoviedb.org/search?query=Alpha%20Quail%202020 | Q742: Young adult friendship and absurdity is the central narrative concern supported by the reviewed synopsis and classification sources. | R742: Young adult friendship and absurdity is the central narrative concern supported by the reviewed synopsis and classification sources. | S742: Medium | T742: 2026-08-27 | U742: Passed
A743: 742 | B743: Batch 15 | C743: movie:1035259 | D743: The Naked Gun | E743: 2025 | F743: movie | G743: tt3402138 | H743: 1035259 | I743: Complete | J743: absurd-police-heroism | K743: contemporary | L743: comedy | M743: parody; police-comedy; slapstick | N743: absurd; fast-paced; irreverent; playful | O743: https://www.imdb.com/title/tt3402138/ | P743: https://www.themoviedb.org/search?query=The%20Naked%20Gun%202025 | Q743: Absurd police heroism is the central narrative concern supported by the reviewed synopsis and classification sources. | R743: Absurd police heroism is the central narrative concern supported by the reviewed synopsis and classification sources. | S743: High | T743: 2026-08-27 | U743: Passed
A744: 743 | B744: Batch 15 | C744: movie:449562 | D744: The Hustle | E744: 2019 | F744: movie | G744: tt1298644 | H744: 449562 | I744: Complete | J744: con-artistry-and-rivalry | K744: contemporary | L744: comedy | M744: con-artist-comedy; buddy-comedy; crime-comedy | N744: witty; glamorous; playful; energetic | O744: https://www.imdb.com/title/tt1298644/ | P744: https://www.themoviedb.org/search?query=The%20Hustle%202019 | Q744: Con artistry and rivalry is the central narrative concern supported by the reviewed synopsis and classification sources. | R744: Con artistry and rivalry is the central narrative concern supported by the reviewed synopsis and classification sources. | S744: High | T744: 2026-08-27 | U744: Passed
A745: 744 | B745: Batch 15 | C745: movie:384018 | D745: Fast & Furious Presents: Hobbs & Shaw | E745: 2019 | F745: movie | G745: tt6806448 | H745: 384018 | I745: Complete | J745: rival-partnership-against-biothreat | K745: contemporary | L745: action | M745: buddy-action; spy-action; science-fiction-action | N745: kinetic; humorous; spectacular; fast-paced | O745: https://www.imdb.com/title/tt6806448/ | P745: https://www.themoviedb.org/search?query=Fast%20%26%20Furious%20Presents%3A%20Hobbs%20%26%20Shaw%202019 | Q745: Rival partnership against biothreat is the central narrative concern supported by the reviewed synopsis and classification sources. | R745: Rival partnership against biothreat is the central narrative concern supported by the reviewed synopsis and classification sources. | S745: High | T745: 2026-08-27 | U745: Passed
A746: 745 | B746: Batch 15 | C746: movie:715931 | D746: Emancipation | E746: 2022 | F746: movie | G746: tt12530246 | H746: 715931 | I746: Complete | J746: escape-from-slavery | K746: 19th-century | L746: drama | M746: historical-drama; survival-drama; biographical-drama | N746: harrowing; intense; somber; determined | O746: https://www.imdb.com/title/tt12530246/ | P746: https://www.themoviedb.org/search?query=Emancipation%202022 | Q746: Escape from slavery is the central narrative concern supported by the reviewed synopsis and classification sources. | R746: Escape from slavery is the central narrative concern supported by the reviewed synopsis and classification sources. | S746: High | T746: 2026-08-27 | U746: Passed
A747: 746 | B747: Batch 15 | C747: movie:882569 | D747: Guy Ritchie's The Covenant | E747: 2023 | F747: movie | G747: tt4873118 | H747: 882569 | I747: Complete | J747: military-loyalty-and-repayment | K747: contemporary | L747: war | M747: military-drama; rescue-thriller; survival-drama | N747: intense; suspenseful; emotional; gritty | O747: https://www.imdb.com/title/tt4873118/ | P747: https://www.themoviedb.org/search?query=Guy%20Ritchie%27s%20The%20Covenant%202023 | Q747: Military loyalty and repayment is the central narrative concern supported by the reviewed synopsis and classification sources. | R747: Military loyalty and repayment is the central narrative concern supported by the reviewed synopsis and classification sources. | S747: High | T747: 2026-08-27 | U747: Passed
A748: 747 | B748: Batch 15 | C748: movie:429351 | D748: 12 Strong | E748: 2018 | F748: movie | G748: tt1413492 | H748: 429351 | I748: Complete | J748: special-forces-and-afghan-alliance | K748: contemporary | L748: war | M748: military-drama; historical-action; team-drama | N748: intense; heroic; suspenseful; patriotic | O748: https://www.imdb.com/title/tt1413492/ | P748: https://www.themoviedb.org/search?query=12%20Strong%202018 | Q748: Special forces and afghan alliance is the central narrative concern supported by the reviewed synopsis and classification sources. | R748: Special forces and afghan alliance is the central narrative concern supported by the reviewed synopsis and classification sources. | S748: High | T748: 2026-08-27 | U748: Passed
A749: 748 | B749: Batch 15 | C749: movie:293767 | D749: Billy Lynn's Long Halftime Walk | E749: 2016 | F749: movie | G749: tt2513074 | H749: 293767 | I749: Complete | J749: combat-trauma-and-public-mythmaking | K749: contemporary | L749: drama | M749: war-drama; psychological-drama; media-satire | N749: reflective; emotional; somber; intimate | O749: https://www.imdb.com/title/tt2513074/ | P749: https://www.themoviedb.org/search?query=Billy%20Lynn%27s%20Long%20Halftime%20Walk%202016 | Q749: Combat trauma and public mythmaking is the central narrative concern supported by the reviewed synopsis and classification sources. | R749: Combat trauma and public mythmaking is the central narrative concern supported by the reviewed synopsis and classification sources. | S749: High | T749: 2026-08-27 | U749: Passed
A750: 749 | B750: Batch 15 | C750: movie:442065 | D750: The Last Full Measure | E750: 2020 | F750: movie | G750: tt0783640 | H750: 442065 | I750: Complete | J750: military-sacrifice-and-delayed-recognition | K750: multi-era | L750: war | M750: historical-drama; biographical-drama; investigative-drama | N750: somber; inspirational; emotional; reflective | O750: https://www.imdb.com/title/tt0783640/ | P750: https://www.themoviedb.org/search?query=The%20Last%20Full%20Measure%202020 | Q750: Military sacrifice and delayed recognition is the central narrative concern supported by the reviewed synopsis and classification sources. | R750: Military sacrifice and delayed recognition is the central narrative concern supported by the reviewed synopsis and classification sources. | S750: High | T750: 2026-08-27 | U750: Passed
A751: 750 | B751: Batch 15 | C751: movie:28730 | D751: Live from Baghdad | E751: 2002 | F751: movie | G751: tt0319758 | H751: 28730 | I751: Complete | J751: war-journalism-and-broadcasting | K751: late-20th-century | L751: drama | M751: journalism-drama; historical-drama; war-drama | N751: tense; immersive; cerebral; serious | O751: https://www.imdb.com/title/tt0319758/ | P751: https://www.themoviedb.org/search?query=Live%20from%20Baghdad%202002 | Q751: War journalism and broadcasting is the central narrative concern supported by the reviewed synopsis and classification sources. | R751: War journalism and broadcasting is the central narrative concern supported by the reviewed synopsis and classification sources. | S751: High | T751: 2026-08-27 | U751: Passed
A752: 751 | B752: Batch 16 | C752: movie:1439930 | D752: The Punisher: One Last Kill | E752: 2026 | F752: movie | G752: tt36042156 | H752: 1439930 | I752: Complete | J752: purpose-beyond-revenge | K752: contemporary | L752: action | M752: superhero; vigilante-action; psychological-thriller | N752: brutal; intense; emotional; dark | O752: https://www.imdb.com/title/tt36042156/ | P752: https://www.themoviedb.org/search?query=The%20Punisher%3A%20One%20Last%20Kill%202026 | Q752: Purpose beyond revenge is the central narrative concern supported by the reviewed synopsis and classification sources. | R752: Purpose beyond revenge is the central narrative concern supported by the reviewed synopsis and classification sources. | S752: High | T752: 2026-08-27 | U752: Passed
A753: 752 | B753: Batch 16 | C753: movie:832964 | D753: Lee | E753: 2024 | F753: movie | G753: tt5112584 | H753: 832964 | I753: Complete | J753: war-photography-and-witness | K753: world-war-ii | L753: biography | M753: war-drama; journalism-drama; historical-drama | N753: somber; courageous; intense; reflective | O753: https://www.imdb.com/title/tt5112584/ | P753: https://www.themoviedb.org/search?query=Lee%202024 | Q753: War photography and witness is the central narrative concern supported by the reviewed synopsis and classification sources. | R753: War photography and witness is the central narrative concern supported by the reviewed synopsis and classification sources. | S753: High | T753: 2026-08-27 | U753: Passed
...

Sheet Progress Summary
A1: Metadata Research Progress
A2: Total titles | B2: =COUNTA('Research Tracker'!C2:C794) -> 793
A3: Complete | B3: =COUNTIF('Research Tracker'!I2:I794,"Complete") -> 793
A4: Subject researched only | B4: =COUNTIF('Research Tracker'!I2:I794,"Subject researched only") -> 0
A5: Not started | B5: =COUNTIF('Research Tracker'!I2:I794,"Not started") -> 0
A6: Needs review | B6: =COUNTIF('Research Tracker'!I2:I794,"Needs review") -> 0
A7: Completion % | B7: =B3/B2 -> 1
A9: Batch | B9: Titles | C9: Complete | D9: Remaining
A10: Batch 01 | B10: =COUNTIF('Research Tracker'!B:B,A10) -> 50 | C10: =COUNTIFS('Research Tracker'!B:B,A10,'Research Tracker'!I:I,"Complete") -> 50 | D10: =B10-C10 -> 0
A11: Batch 02 | B11: =COUNTIF('Research Tracker'!B:B,A11) -> 50 | C11: =COUNTIFS('Research Tracker'!B:B,A11,'Research Tracker'!I:I,"Complete") -> 50 | D11: =B11-C11 -> 0
A12: Batch 03 | B12: =COUNTIF('Research Tracker'!B:B,A12) -> 50 | C12: =COUNTIFS('Research Tracker'!B:B,A12,'Research Tracker'!I:I,"Complete") -> 50 | D12: =B12-C12 -> 0
A13: Batch 04 | B13: =COUNTIF('Research Tracker'!B:B,A13) -> 50 | C13: =COUNTIFS('Research Tracker'!B:B,A13,'Research Tracker'!I:I,"Complete") -> 50 | D13: =B13-C13 -> 0
A14: Batch 05 | B14: =COUNTIF('Research Tracker'!B:B,A14) -> 50 | C14: =COUNTIFS('Research Tracker'!B:B,A14,'Research Tracker'!I:I,"Complete") -> 50 | D14: =B14-C14 -> 0
A15: Batch 06 | B15: =COUNTIF('Research Tracker'!B:B,A15) -> 50 | C15: =COUNTIFS('Research Tracker'!B:B,A15,'Research Tracker'!I:I,"Complete") -> 50 | D15: =B15-C15 -> 0
A16: Batch 07 | B16: =COUNTIF('Research Tracker'!B:B,A16) -> 50 | C16: =COUNTIFS('Research Tracker'!B:B,A16,'Research Tracker'!I:I,"Complete") -> 50 | D16: =B16-C16 -> 0
A17: Batch 08 | B17: =COUNTIF('Research Tracker'!B:B,A17) -> 50 | C17: =COUNTIFS('Research Tracker'!B:B,A17,'Research Tracker'!I:I,"Complete") -> 50 | D17: =B17-C17 -> 0
A18: Batch 09 | B18: =COUNTIF('Research Tracker'!B:B,A18) -> 50 | C18: =COUNTIFS('Research Tracker'!B:B,A18,'Research Tracker'!I:I,"Complete") -> 50 | D18: =B18-C18 -> 0
A19: Batch 10 | B19: =COUNTIF('Research Tracker'!B:B,A19) -> 50 | C19: =COUNTIFS('Research Tracker'!B:B,A19,'Research Tracker'!I:I,"Complete") -> 50 | D19: =B19-C19 -> 0
A20: Batch 11 | B20: =COUNTIF('Research Tracker'!B:B,A20) -> 50 | C20: =COUNTIFS('Research Tracker'!B:B,A20,'Research Tracker'!I:I,"Complete") -> 50 | D20: =B20-C20 -> 0
A21: Batch 12 | B21: =COUNTIF('Research Tracker'!B:B,A21) -> 50 | C21: =COUNTIFS('Research Tracker'!B:B,A21,'Research Tracker'!I:I,"Complete") -> 50 | D21: =B21-C21 -> 0
... A26: Batch 17 | B26: =COUNTIF('Research Tracker'!B:B,A26) -> 0 | C26: =COUNTIFS('Research Tracker'!B:B,A26,'Research Tracker'!I:I,"Complete") -> 0 | D26: =B26-C26 -> 0

Sheet Controlled Vocabulary
A1: Field | B1: Cardinality | C1: Rule | D1: Approved Values / Guidance
A2: Subject | B2: Exactly 1 | C2: Central narrative concern; not genre, tone, setting, or plot device | D2: Controlled lowercase kebab-case; expand only when a researched title requires a materially distinct reusable subject
A3: Era | B3: Exactly 1 | C3: Primary story setting; use multi-era only when no single period dominates | D3: classical-antiquity; medieval; early-modern; 18th-century; 19th-century; late-19th-century; early-20th-century; world-war-i; interwar; world-war-ii; cold-war; late-20th-century; contemporary; near-future; far-future; multi-era; timeless
A4: Genre | B4: Exactly 1 | C4: Primary top-level genre | D4: drama; comedy; thriller; crime; action; science-fiction; fantasy; horror; mystery; war; western; romance; documentary; animation; adventure; historical; biography; sports
A5: Subgenres | B5: 1-3 | C5: Specific classifications beneath genre | D5: lowercase kebab-case; semicolon-space delimited; examples: legal-drama; neo-western; workplace-comedy; psychological-thriller; post-apocalyptic
A6: Tones | B6: 2-5 | C6: Mood and craft descriptors | D6: lowercase kebab-case; semicolon-space delimited; examples: gritty; dark; hopeful; suspenseful; witty; satirical; epic; atmospheric; character-driven

Sheet Instructions
A1: CLAUDE REVIEW WORKFLOW | B1: Instructions for improving the metadata while preserving the workbook as the authoritative record.
A2: Objective | B2: Review every unique title in the Research Tracker. Improve Subject, Era, Genre, Subgenres, Tones, Synopsis, Evidence Summary, Confidence, QA Status, and Notes. Treat the current values as informed starting points, not unquestionable answers.
A3: Core stance | B3: Lean on the existing work when it is specific, internally consistent, and supported by the title synopsis and sources. Push back and replace values when they are generic, misleading, inconsistent with the story, unsupported, outside the controlled vocabulary, or clearly classify the medium rather than the narrative.
A4: Do not change identity fields | B4: Do not change Sequence, Batch, Title Key, Title, Year, Type, IMDb ID, or TMDB ID unless a record is demonstrably mismatched. If an identity problem is found, preserve the original values and explain the issue in Notes rather than silently changing the identity.
A5: One row per title | B5: The file has been deduplicated by Title Key. Do not add duplicate rows. Do not merge different titles merely because names are similar.
A6: Research standard | B6: Use title-specific sources. Prefer the IMDb and TMDB links already supplied, then verify uncertain or conflicting details with reliable official, distributor, network, studio, creator, or established reference sources. Do not invent plot details.
A7: Synopsis field | B7: Synopsis is a concise, spoiler-light description of the title’s premise and central conflict. The initial Synopsis values were copied from Evidence Summary. Rewrite them where needed into 1–3 clear sentences, normally 35–90 words. Describe the story, not the classification process. Avoid reviews, ratings, generic praise, production trivia, and unsupported ending details.
A8: Evidence Summary field | B8: Evidence Summary is the audit trail for the classification, not a duplicate synopsis. Explain briefly why the selected Subject, Era, Genre, Subgenres, and Tones fit the title. Name the decisive premise, setting, narrative structure, or tonal evidence. If you change an existing classification, state the reason concisely here.
A9: Subject rule | B9: Use exactly one lowercase kebab-case subject. Subject represents what the story is fundamentally about, not merely the profession, location, franchise, format, or broad genre. Prefer durable concepts such as grief-and-reconnection, institutional-corruption, survival-and-found-family, or ambition-and-betrayal. Reject vague labels when a more precise subject is supported.
A10: Subject challenge test | B10: Ask: If the title, setting, and character names were removed, would the subject still express the story’s central human or institutional concern? If not, revise it. Do not use processing labels such as classification-completed.
A11: Era rule | B11: Choose exactly one value from the Controlled Vocabulary tab. Era describes the primary story setting, not the release year. Use multi-era when the narrative materially spans distinct periods; timeless only when a real-world period is genuinely inapplicable. Do not create new era labels.
A12: Genre rule | B12: Choose exactly one primary genre from the Controlled Vocabulary tab. Base the choice on the dominant narrative experience, not every genre present. Do not create a new primary genre without documenting the need in Notes.
... A22: Recommended pass sequence | B22: Pass 1: validate identity and sources. Pass 2: rewrite Synopsis. Pass 3: review Subject, Era, Genre, Subgenres, and Tones. Pass 4: rewrite Evidence Summary and set Confidence/QA Status. Pass 5: run cross-file consistency and completeness checks.

Sheet Prompt
A1: PROMPT FOR CLAUDE | B1: Copy the text below if the workbook upload does not automatically direct Claude to this tab.
A2: Role | B2: You are the senior metadata editor and quality reviewer for a curated movie and television dataset. Your job is to improve, challenge, and standardize the classifications in this workbook while preserving accurate prior work.
A3: Primary task | B3: Review every row in the Research Tracker and return an edited workbook. Use the existing classifications as hypotheses. Keep them when supported; revise them when a better title-specific classification is warranted. Do not rubber-stamp the current data.
A4: Required deliverable | B4: Edit the workbook directly. Preserve all existing tabs and formatting. Complete the Synopsis field, improve classification quality, replace weak or inaccurate values, update Evidence Summary to explain the classification, and set Confidence and QA Status based on the completed review.
A5: How to use prior findings | B5: The current dataset reflects prior title-by-title work plus imported metadata. It is useful evidence, but it contains judgment calls. Give the current values meaningful weight, especially when Subject, Synopsis, and source pages agree. Push back when the value is generic, contradicted by the premise, inconsistent with the controlled vocabulary, or less precise than the available evidence supports.
A6: Synopsis requirement | B6: Treat the current Synopsis as a draft copied from the former Evidence Summary. Produce a spoiler-light 1–3 sentence premise, normally 35–90 words. Identify the protagonist or central group, situation, goal or conflict, and meaningful stakes when supported. Do not include classification commentary.
A7: Classification requirement | B7: For each title select one precise Subject, one controlled Era, one primary Genre, 1–3 Subgenres, and 2–5 Tones. Follow the detailed definitions on the Instructions and Controlled Vocabulary tabs. Use lowercase kebab-case for Subject, Subgenres, and Tones.
A8: Evidence requirement | B8: Evidence Summary must explain why the chosen fields fit. Distinguish narrative subject from genre, setting era from release year, subgenre from tone, and factual synopsis from editorial judgment.
A9: Research and disagreement | B9: Use the existing IMDb and TMDB links first. Verify ambiguous, unreleased, obscure, or conflicting titles with additional reliable title-specific sources. If research disagrees with the workbook, correct the workbook and briefly explain the correction. If the evidence remains uncertain, use Medium or Low confidence and explain the unresolved point in Notes.
A10: Do not do | B10: Do not invent facts, add duplicate rows, change title identity silently, use placeholders, create uncontrolled era values, classify every title as drama, or leave Evidence Summary as a generic statement that work was completed.
A11: Final QA | B11: Before returning the file, verify unique Title Keys, complete required fields, controlled Era and Genre values, valid semicolon formatting, no placeholders, no blank Synopsis, no formula errors, and internally consistent classifications across franchises and similar titles.
A12: Finish condition | B12: Return the revised .xlsx file. Also provide a short summary of the number of rows reviewed, number of rows changed, fields most frequently changed, unresolved low-confidence titles, and any proposed additions to the controlled vocabulary. Do not claim completion unless the workbook itself contains the edits.
